Workbook

Sheet Cost Summary & Dashboard
A1: BÁO CÁO TỔNG HỢP NGUỒN VỐN VÀ DỰ TOÁN CHI PHÍ DỰ ÁN (HOÀN CHỈNH)
A2: Dự án: Hệ thống Bán hàng Online ABC Wear | Mã gói thầu: ABC-WSS-PM_26I_09 | Nhà thầu: Nhóm 09
A4: TỔNG GIÁ TRỊ HỢP ĐỒNG (SAU VAT) | D4: GIÁ TRỊ TRƯỚC THUẾ (NET) | G4: TỔNG THUẾ VAT (10%) | J4: TỔNG GIỜ CÔNG NHÂN LỰC
A5: ='Cost Summary & Dashboard'!H23 | D5: ='Cost Summary & Dashboard'!E23 | G5: ='Cost Summary & Dashboard'!G23 | J5: ='Resource & Rates'!E18
A8: 1. TỔNG HỢP CHI PHÍ THEO PHẠM VI CUNG CẤP (WBS CATEGORIES)
A9: STT | B9: Hạng Mục Dịch Vụ / Phân Hệ | C9: Mô Tả Cung Cấp | D9: ĐVT | E9: Giá Trước VAT (VNĐ) | F9: Thuế Suất | G9: Tiền Thuế VAT (VNĐ) | H9: Giá Sau VAT (VNĐ) | I9: Tỷ Trọng (%) | J9: Ghi Chú
A10: 1 | B10: Phân tích hệ thống (System Analysis) | C10: Khảo sát AS-IS, đặc tả SRS, NFR & luồng TO-BE, đóng băng M1 | D10: Gói | E10: ='Detailed Estimate'!F10 | F10: ='Detailed Estimate'!G10 | G10: ='Detailed Estimate'!H10 | H10: ='Detailed Estimate'!I10 | I10: =H10/$H$16 | J10: Tham chiếu WBS chi tiết
A11: 2 | B11: Thiết kế & Phát triển Web Selling Site | C11: Kiến trúc HLD/LLD, Selling DB, UI/UX, 16 tính năng E-commerce, CDN & CI/CD | D11: Hệ thống | E11: ='Detailed Estimate'!F35 | F11: ='Detailed Estimate'!G35 | G11: ='Detailed Estimate'!H35 | H11: ='Detailed Estimate'!I35 | I11: =H11/$H$16 | J11: Tham chiếu WBS chi tiết
A12: 3 | B12: Tích hợp Main System | C12: Adapter đồng bộ sản phẩm, tồn kho, đơn hàng, khách hàng với hệ thống lõi | D12: Hệ thống | E12: ='Detailed Estimate'!F45 | F12: ='Detailed Estimate'!G45 | G12: ='Detailed Estimate'!H45 | H12: ='Detailed Estimate'!I45 | I12: =H12/$H$16 | J12: Tham chiếu WBS chi tiết
A13: 4 | B13: Kiểm thử vận hành (Operation Test) | C13: SIT, kịch bản test case, kiểm thử hiệu năng P95<=2s, Security & UAT M4 | D13: Bộ | E13: ='Detailed Estimate'!F53 | F13: ='Detailed Estimate'!G53 | G13: ='Detailed Estimate'!H53 | H13: ='Detailed Estimate'!I53 | I13: =H13/$H$16 | J13: Tham chiếu WBS chi tiết
A14: 5 | B14: Bàn giao & Cut-over | C14: Chuyển đổi CSDL, đào tạo, tài liệu HDSD/vận hành, Cut-over & 01 tháng Hypercare | D14: Hệ thống | E14: ='Detailed Estimate'!F60 | F14: ='Detailed Estimate'!G60 | G14: ='Detailed Estimate'!H60 | H14: ='Detailed Estimate'!I60 | I14: =H14/$H$16 | J14: Tham chiếu WBS chi tiết
A15: 6 | B15: Bảo hành & Hỗ trợ kỹ thuật | C15: Bảo hành 12 tháng sau Go-live (2.900.000 VNĐ/tháng, SLA 24/7) | D15: 12 Tháng | E15: ='Detailed Estimate'!F63 | F15: ='Detailed Estimate'!G63 | G15: ='Detailed Estimate'!H63 | H15: ='Detailed Estimate'!I63 | I15: =H15/$H$16 | J15: Tham chiếu WBS chi tiết
A16: TỔNG CỘNG HẠNG MỤC DỊCH VỤ | E16: =SUM(E10:E15) | F16: 0.1 | G16: =SUM(G10:G15) | H16: =SUM(H10:H15) | I16: =SUM(I10:I15)
A18: 2. PHÂN TÍCH CƠ SỞ CẤU THÀNH CHI PHÍ VÀ DỰ PHÒNG (COST BASIS & CONTINGENCY)
A19: Chi phí nhân công trực tiếp (Direct Labor Cost) | C19: 3.200 giờ công / 12 nhân sự chuyên trách | E19: ='Resource & Rates'!F18 | F19: 0.1 | G19: =ROUND(E19*F19, 0) | H19: =E19+G19 | I19: =H19/$H$23 | J19: Căn cứ ma trận giờ công & đơn giá
A20: Chi phí hạ tầng Cloud DEV/UAT & Công cụ đo tải trực tiếp | C20: Môi trường Cloud thử nghiệm, công cụ đo tải P95, SMS/OTP | E20: 28500000 | F20: 0.1 | G20: =ROUND(E20*F20, 0) | H20: =E20+G20 | I20: =H20/$H$23 | J20: Dự phòng rủi ro được xác định rõ ràng
A21: Chi phí dự phòng rủi ro kỹ thuật & quản lý thay đổi (Contingency Reserve) | C21: Dự phòng rủi ro và quản lý thay đổi theo yêu cầu hồ sơ (21,7%) | E21: 236809091 | F21: 0.1 | G21: =ROUND(E21*F21, 0) | H21: =E21+G21 | I21: =H21/$H$23 | J21: Tổng tiền thuế GTGT phải nộp
A22: Thuế Giá trị gia tăng VAT (10% áp dụng cho toàn bộ gói thầu) | C22: Thuế GTGT 10% theo Luật Thuế hiện hành | F22: 0.1 | G22: =G19+G20+G21 | H22: =G22 | I22: =H22/$H$23
A23: TỔNG GIÁ TRỊ HỢP ĐỒNG TRỌN GÓI (CONTRACT PRICE) | E23: =E19+E20+E21 | F23: 0.1 | G23: =G22 | H23: =E23+G23 | I23: 1

Sheet Detailed Estimate
A1: BẢNG CHÀO GIÁ VÀ DỰ TOÁN CHI TIẾT THEO WBS (46 WORK PACKAGES)
A2: Minh bạch chi tiết Giá trước VAT - Thuế suất VAT - Tiền thuế VAT - Giá sau VAT cho từng gói công việc
A4: STT WBS | B4: Hạng Mục / Công Việc Chi Tiết | C4: Mô Tả Kỹ Thuật / Deliverables | D4: Khối Lượng | E4: ĐVT | F4: Giá Trước VAT (VNĐ) | G4: Thuế Suất VAT | H4: Tiền Thuế VAT (VNĐ) | I4: Giá Sau VAT (VNĐ) | J4: Tỷ Trọng (%)
A5: 1 | B5: Phân tích hệ thống (System Analysis)
A6: 1.1 | B6: Khảo sát hiện trạng | C6: Hội thảo nghiệp vụ, khảo sát Main System và chi nhánh, báo cáo hiện trạng | D6: 1 | E6: Gói | F6: 32727273 | G6: 0.1 | H6: =ROUND(F6*G6, 0) | I6: 36000000 | J6: =I6/$I$64
A7: 1.2 | B7: Đặc tả yêu cầu chức năng (SRS) | C7: Đặc tả sản phẩm, đơn hàng, khách hàng và thông báo | D7: 1 | E7: Gói | F7: 40000000 | G7: 0.1 | H7: =ROUND(F7*G7, 0) | I7: 44000000 | J7: =I7/$I$64
A8: 1.3 | B8: Đặc tả tích hợp, NFR và luồng mới | C8: Kết nối Main System; sẵn sàng 24/7; đáp ứng không quá 2 giây; bảo mật và dữ liệu cá nhân; luồng vận hành mới | D8: 1 | E8: Gói | F8: 30909091 | G8: 0.1 | H8: =ROUND(F8*G8, 0) | I8: 34000000 | J8: =I8/$I$64
A9: 1.4 | B9: Xác lập Product Backlog nền tảng | C9: Rà soát, thống nhất đặc tả yêu cầu, Product Backlog và Định nghĩa Hoàn thành | D9: 1 | E9: Gói | F9: 14545455 | G9: 0.1 | H9: =ROUND(F9*G9, 0) | I9: 16000000 | J9: =I9/$I$64
B10: CỘNG PHÂN TÍCH HỆ THỐNG (SYSTEM ANALYSIS) | F10: =SUM(F6:F9) | G10: 0.1 | H10: =SUM(H6:H9) | I10: =SUM(I6:I9) | J10: =I10/$I$64
A11: 2 | B11: Thiết kế & Phát triển Web Selling Site System
A12: 2.1 | B12: Thiết kế kiến trúc và an toàn thông tin | C12: Kiến trúc sẵn sàng 24/7, tính toán quy mô, bảo vệ dữ liệu cá nhân, giám sát và sao lưu | D12: 1 | E12: Gói | F12: 33636364 | G12: 0.1 | H12: =ROUND(F12*G12, 0) | I12: 37000000 | J12: =I12/$I$64
A13: 2.2 | B13: Thiết kế Selling DB | C13: Mô hình logic và vật lý, từ điển dữ liệu, phân quyền truy cập | D13: 1 | E13: Gói | F13: 21818182 | G13: 0.1 | H13: =ROUND(F13*G13, 0) | I13: 24000000 | J13: =I13/$I$64
A14: 2.3 | B14: Thiết kế giao diện và Menu Layer | C14: Sơ đồ trang, khung dây luồng mua, bản mẫu sản phẩm, đơn hàng và khách hàng | D14: 1 | E14: Gói | F14: 52727273 | G14: 0.1 | H14: =ROUND(F14*G14, 0) | I14: 58000000 | J14: =I14/$I$64
A15: 2.4 | B15: Thiết kế chi tiết và phê duyệt | C15: Thiết kế chi tiết theo phân hệ; rà soát kiến trúc, cơ sở dữ liệu và đặc tả giao tiếp | D15: 1 | E15: Gói | F15: 36363636 | G15: 0.1 | H15: =ROUND(F15*G15, 0) | I15: 40000000 | J15: =I15/$I$64
A16: 2.5 | B16: Môi trường và khung ứng dụng | C16: Môi trường DEV, SIT, UAT, PROD, đường ống CI/CD, khung ứng dụng, giả lập Main System; gồm chi phí đám mây | D16: 1 | E16: Gói | F16: 72727273 | G16: 0.1 | H16: =ROUND(F16*G16, 0) | I16: 80000000 | J16: =I16/$I$64
A17: 2.6 | B17: Đăng ký tài khoản | C17: Giao diện đăng ký, API và xác thực OTP hiệu lực 05 phút | D17: 1 | E17: Tính năng | F17: 10909091 | G17: 0.1 | H17: =ROUND(F17*G17, 0) | I17: 12000000 | J17: =I17/$I$64
A18: 2.7 | B18: Đăng nhập và quản lý phiên | C18: Đăng nhập, đăng xuất, Refresh Token, khóa tài khoản khi đăng nhập sai quá 5 lần | D18: 1 | E18: Tính năng | F18: 9545454.6 | G18: 0.1 | H18: =ROUND(F18*G18, 0) | I18: 10500000 | J18: =I18/$I$64
A19: 2.8 | B19: Quên mật khẩu và đổi mật khẩu | C19: Đặt lại mật khẩu bằng mã xác nhận có thời hạn | D19: 1 | E19: Tính năng | F19: 5454545.5 | G19: 0.1 | H19: =ROUND(F19*G19, 0) | I19: 6000000 | J19: =I19/$I$64
A20: 2.9 | B20: Hồ sơ cá nhân và sổ địa chỉ | C20: Cập nhật hồ sơ và quản lý nhiều địa chỉ giao hàng | D20: 1 | E20: Tính năng | F20: 9545454.6 | G20: 0.1 | H20: =ROUND(F20*G20, 0) | I20: 10500000 | J20: =I20/$I$64
A21: 2.10 | B21: Lịch sử đơn hàng của thành viên | C21: Tra cứu các đơn hàng đã đặt và trạng thái xử lý trên kênh web | D21: 1 | E21: Tính năng | F21: 5454545.5 | G21: 0.1 | H21: =ROUND(F21*G21, 0) | I21: 6000000 | J21: =I21/$I$64
A22: 2.11 | B22: Đồng ý dữ liệu cá nhân và xóa tài khoản | C22: Ghi nhận đồng ý, rút đồng ý và xử lý yêu cầu xóa tài khoản | D22: 1 | E22: Tính năng | F22: 6363636.4 | G22: 0.1 | H22: =ROUND(F22*G22, 0) | I22: 7000000 | J22: =I22/$I$64
A23: 2.12 | B23: Tìm kiếm sản phẩm | C23: Tìm theo từ khóa, gợi ý tức thì dưới 200 mili-giây, tiếng Việt không dấu, phân trang | D23: 1 | E23: Tính năng | F23: 17272727 | G23: 0.1 | H23: =ROUND(F23*G23, 0) | I23: 19000000 | J23: =I23/$I$64
... A34: 2.23 | B34: Điều phối giai đoạn xây dựng | C34: Quản lý tiến độ, rủi ro và báo cáo trong quá trình thiết kế, lập trình | D34: 1 | E34: Gói | F34: 37727273 | G34: 0.1 | H34: =ROUND(F34*G34, 0) | I34: 41500000 | J34: =I34/$I$64
B35: CỘNG THIẾT KẾ & PHÁT TRIỂN WEB SELLING SITE SYSTEM | F35: =SUM(F12:F34) | G35: 0.1 | H35: =SUM(H12:H34) | I35: =SUM(I12:I34) | J35: =I35/$I$64
A36: 3 | B36: Tích hợp Main System
A37: 3.1 | B37: Đặc tả giao diện tích hợp | C37: Giao diện sản phẩm, đơn hàng, khách hàng; quy tắc thử lại tự động và đối soát | D37: 1 | E37: Gói | F37: 23181818 | G37: 0.1 | H37: =ROUND(F37*G37, 0) | I37: 25500000 | J37: =I37/$I$64
A38: 3.2 | B38: Đồng bộ danh mục, giá và khuyến mại | C38: Bộ kết nối đồng bộ từ Main System, lịch chạy tự động và nhật ký giao dịch | D38: 1 | E38: Tính năng | F38: 12727273 | G38: 0.1 | H38: =ROUND(F38*G38, 0) | I38: 14000000 | J38: =I38/$I$64
A39: 3.3 | B39: Đồng bộ tồn kho | C39: Chu kỳ không quá 15 phút, xử lý lệch tồn kho và gửi cảnh báo | D39: 1 | E39: Tính năng | F39: 16818182 | G39: 0.1 | H39: =ROUND(F39*G39, 0) | I39: 18500000 | J39: =I39/$I$64
A40: 3.4 | B40: Đẩy đơn hàng sang Main System | C40: Hàng đợi tin nhắn, thử lại tự động, khóa chống trùng lặp đơn hàng | D40: 1 | E40: Tính năng | F40: 19090909 | G40: 0.1 | H40: =ROUND(F40*G40, 0) | I40: 21000000 | J40: =I40/$I$64
A41: 3.5 | B41: Nhận trạng thái xử lý và giao hàng | C41: Cập nhật trạng thái từ Main System và thông báo cho khách hàng | D41: 1 | E41: Tính năng | F41: 15000000 | G41: 0.1 | H41: =ROUND(F41*G41, 0) | I41: 16500000 | J41: =I41/$I$64
A42: 3.6 | B42: Đồng bộ dữ liệu khách hàng | C42: Bộ kết nối đồng bộ hồ sơ khách hàng hai chiều giữa Selling DB và Main System | D42: 1 | E42: Tính năng | F42: 10454545 | G42: 0.1 | H42: =ROUND(F42*G42, 0) | I42: 11500000 | J42: =I42/$I$64
A43: 3.7 | B43: Đối soát và kiểm thử kết nối thật | C43: Báo cáo lệch dữ liệu hằng ngày và kiểm thử kết nối cùng đội CNTT Main System | D43: 1 | E43: Gói | F43: 20454545 | G43: 0.1 | H43: =ROUND(F43*G43, 0) | I43: 22500000 | J43: =I43/$I$64
A44: 3.8 | B44: Điều phối tích hợp | C44: Phối hợp đội CNTT ABC Wear trong suốt quá trình kết nối các luồng dữ liệu | D44: 1 | E44: Gói | F44: 9545454.6 | G44: 0.1 | H44: =ROUND(F44*G44, 0) | I44: 10500000 | J44: =I44/$I$64
B45: CỘNG TÍCH HỢP MAIN SYSTEM | F45: =SUM(F37:F44) | G45: 0.1 | H45: =SUM(H37:H44) | I45: =SUM(I37:I44) | J45: =I45/$I$64
A46: 4 | B46: Kiểm thử vận hành (Operation Test)
A47: 4.1 | B47: Chuẩn bị kiểm thử | C47: Kế hoạch kiểm thử, kịch bản kiểm thử theo phân hệ, dữ liệu kiểm thử và ma trận truy vết | D47: 1 | E47: Gói | F47: 46363636 | G47: 0.1 | H47: =ROUND(F47*G47, 0) | I47: 51000000 | J47: =I47/$I$64
A48: 4.2 | B48: Kiểm thử tích hợp hệ thống | C48: Kiểm thử tích hợp sản phẩm, khách hàng, đơn hàng, luồng đồng bộ và luồng đầu-cuối | D48: 1 | E48: Gói | F48: 46818182 | G48: 0.1 | H48: =ROUND(F48*G48, 0) | I48: 51500000 | J48: =I48/$I$64
A49: 4.3 | B49: Kiểm thử hiệu năng | C49: Đo kiểm chịu tải 5.000 người dùng đồng thời đạt P95 không quá 2 giây; gồm công cụ đo tải | D49: 1 | E49: Gói | F49: 28181818 | G49: 0.1 | H49: =ROUND(F49*G49, 0) | I49: 31000000 | J49: =I49/$I$64
A50: 4.4 | B50: Kiểm thử an toàn bảo mật | C50: Kiểm thử bảo mật theo chuẩn OWASP Top 10 và phân quyền; gồm công cụ quét lỗ hổng | D50: 1 | E50: Gói | F50: 24090909 | G50: 0.1 | H50: =ROUND(F50*G50, 0) | I50: 26500000 | J50: =I50/$I$64
A51: 4.5 | B51: Sửa lỗi và kiểm thử hồi quy | C51: Khắc phục lỗi phát sinh và chạy lại toàn bộ kịch bản kiểm thử hồi quy tự động | D51: 1 | E51: Gói | F51: 33181818 | G51: 0.1 | H51: =ROUND(F51*G51, 0) | I51: 36500000 | J51: =I51/$I$64
...

Sheet Resource & Rates
A1: CƠ SỞ ĐƠN GIÁ GIỜ CÔNG VÀ PHÂN BỔ NGUỒN LỰC NHÂN SỰ
A2: Cấu thành chi phí nhân công trực tiếp (3.200 giờ công / 12 nhân sự chuyên trách)
A4: STT | B4: Họ và Tên | C4: Vị Trí / Vai Trò | D4: Đơn Giá Chưa VAT (VNĐ/h) | E4: Tổng Số Giờ | F4: Thành Tiền Chưa VAT (VNĐ) | G4: Tỷ Trọng (%) | H4: Ghi Chú Module Phụ Trách
A5: 1 | B5: Nguyễn Đức Tân | C5: PM - Quản lý dự án | D5: 320000 | E5: 260 | F5: =D5*E5 | G5: =F5/$F$18 | H5: Quản trị tổng thể, điều phối Scope/Cost/Schedule
A6: 2 | B6: Nguyễn Hải Đăng | C6: SA - Kiến trúc hệ thống | D6: 300000 | E6: 270 | F6: =D6*E6 | G6: =F6/$F$18 | H6: Thiết kế kiến trúc 24/7, Selling DB & API Spec
A7: 3 | B7: Đinh Đức Thắng | C7: BA - Phân tích nghiệp vụ | D7: 280000 | E7: 340 | F7: =D7*E7 | G7: =F7/$F$18 | H7: Khảo sát AS-IS, SRS, luồng TO-BE & UAT
A8: 4 | B8: Nguyễn Thị Thu Thủy | C8: UX - Thiết kế giao diện | D8: 260000 | E8: 190 | F8: =D8*E8 | G8: =F8/$F$18 | H8: UI/UX, Wireframe, Mockup, Menu Layer
A9: 5 | B9: Nguyễn Thị Phương | C9: DEV1 - Lập trình chính | D9: 260000 | E9: 390 | F9: =D9*E9 | G9: =F9/$F$18 | H9: Phân hệ Khách hàng và Tích hợp
A10: 6 | B10: Vũ Tuấn A | C10: DEV2 - Lập trình viên | D10: 250000 | E10: 370 | F10: =D10*E10 | G10: =F10/$F$18 | H10: Phân hệ Sản phẩm, Tìm kiếm và Tồn kho
A11: 7 | B11: Nguyễn Ngọc B | C11: DEV3 - Lập trình viên | D11: 250000 | E11: 370 | F11: =D11*E11 | G11: =F11/$F$18 | H11: Phân hệ Đơn hàng, Thanh toán và Logistics
A12: 8 | B12: Nguyễn Hữu C | C12: QC1 - Kiểm thử trưởng | D12: 250000 | E12: 240 | F12: =D12*E12 | G12: =F12/$F$18 | H12: SIT, Kiểm thử hiệu năng P95<=2s & Tự động hóa
A13: 9 | B13: Phạm Minh D | C13: QC2 - Chuyên viên QC | D13: 230000 | E13: 210 | F13: =D13*E13 | G13: =F13/$F$18 | H13: Kiểm thử chức năng, Security OWASP & UAT
A14: 10 | B14: Trần Hùng E | C14: OPS - Kỹ sư DevOps/Infra | D14: 250000 | E14: 170 | F14: =D14*E14 | G14: =F14/$F$18 | H14: Thiết lập Cloud DEV/PROD, CI/CD & Cut-over
A15: 11 | B15: Nguyễn Văn F | C15: DEV4 - Lập trình viên | D15: 210000 | E15: 190 | F15: =D15*E15 | G15: =F15/$F$18 | H15: Cổng thanh toán và Tích hợp API Gateway
A16: 12 | B16: Nguyễn Văn G | C16: DEV5 - Lập trình viên | D16: 208947.37 | E16: 190 | F16: =D16*E16 | G16: =F16/$F$18 | H16: Cơ sở dữ liệu Selling DB và Tối ưu hiệu năng
A18: TỔNG CỘNG CHI PHÍ NHÂN CÔNG TRỰC TIẾP (CHƯA VAT) | E18: =SUM(E5:E16) | F18: =SUM(F5:F16) | G18: =SUM(G5:G16)

Sheet Payment Schedule
A1: KẾ HOẠCH TẠM ỨNG VÀ THANH TOÁN THEO MỐC MILESTONE
A2: Khớp 100% Giá trị Hợp đồng sau VAT (1.200.000.000 VNĐ) theo Điều kiện Cụ thể của Hợp đồng E-ĐKCT
A4: Đợt TT | B4: Mốc Milestone / Giai Đoạn | C4: Tỷ Lệ (%) | D4: Giá Trị Thanh Toán (VNĐ) | E4: Điều Kiện & Sản Phẩm Nghiệm Thu | F4: Thời Gian Dự Kiến
A5: Đợt 1 | B5: Tạm ứng hợp đồng (Advance Payment) | C5: 0.2 | D5: ='Cost Summary & Dashboard'!H23*C5 | E5: Ngay sau khi ký hợp đồng & nộp Bảo lãnh tạm ứng ngân hàng | F5: Tháng 03/2026
A6: Đợt 2 | B6: Nghiệm thu Sprint 1–2 (Khách hàng & Danh mục) | C6: 0.2 | D6: ='Cost Summary & Dashboard'!H23*C6 | E6: Biên bản nghiệm thu Product Increment Sprint 2 đạt yêu cầu | F6: Tháng 04/2026
A7: Đợt 3 | B7: Nghiệm thu Sprint 3–5 (Giỏ hàng & Đặt hàng) | C7: 0.25 | D7: ='Cost Summary & Dashboard'!H23*C7 | E7: Biên bản nghiệm thu Product Increment Sprint 5 đạt yêu cầu | F7: Tháng 05/2026
A8: Đợt 4 | B8: Nghiệm thu Sprint 6–8 & Cut-over 01/07 | C8: 0.25 | D8: ='Cost Summary & Dashboard'!H23*C8 | E8: Biên bản nghiệm thu Product Increment Sprint 8, kiểm thử vận hành đạt yêu cầu và hoàn tất Cut-over 01/07/2026 | F8: Tháng 07/2026
A9: Đợt 5 | B9: Thanh lý hợp đồng & chuyển sang bảo hành | C9: 0.1 | D9: ='Cost Summary & Dashboard'!H23*C9 | E9: Hoàn thành 01 tháng Hypercare, bàn giao đủ 04 bộ tài liệu và nộp cam kết bảo hành 12 tháng | F9: Tháng 08/2026
A10: TỔNG CỘNG GIÁ TRỊ THANH TOÁN (SAU VAT) | C10: =SUM(C5:C9) | D10: =SUM(D5:D9)
